<?xml version="1.0"?>
<sdf version="1.8">
  <model name="Schunk_Gripper">
    <!--To enable faster simulation, the collision geometry in this model
         consists of multiple spheres. These are arranged in a line along each
         finger, with two additional spheres forming a triangle at each finger
         tip.-->
    <link name="gripper_base">
      <pose>0 -0.049133 0 0 0 0</pose>
      <inertial>
        <pose>4.93e-05 -0.0145 0.058 0 0 0</pose>
        <mass>0.082</mass>
        <inertia>
          <ixx>0.162992</ixx>
          <ixy>0</ixy>
          <ixz>0</ixz>
          <iyy>0.162992</iyy>
          <iyz>0</iyz>
          <izz>0.164814</izz>
        </inertia>
      </inertial>
      <visual name="visual">
        <geometry>
          <box>
            <size>0.146 0.0725 0.049521</size>
          </box>
        </geometry>
        <material>
          <ambient>0.3 0.3 0.3 1</ambient>
          <diffuse>0.7 0.7 0.7 1</diffuse>
          <specular>0.01 0.01 0.01 1</specular>
          <emissive>0 0 0 1</emissive>
        </material>
      </visual>
      <collision name="collision">
        <geometry>
          <box>
            <size>0.146 0.0725 0.05</size>
          </box>
        </geometry>
        <drake:proximity_properties>
          <drake:rigid_hydroelastic/>
          <!-- <drake:mesh_resolution_hint>0.1</drake:mesh_resolution_hint>
          <drake:hydroelastic_modulus>5e7</drake:hydroelastic_modulus>
          <drake:hunt_crossley_dissipation>1.25</drake:hunt_crossley_dissipation> -->
          <drake:relaxation_time>0.1</drake:relaxation_time>
        </drake:proximity_properties>
      </collision>
    </link>

    <frame name="body_frame">
      <pose relative_to="gripper_base"/>
    </frame>

    <link name="left_finger">
      <pose>-0.008 0.029 0 0 0 0</pose>
      <inertial>
        <mass>0.05</mass>
        <inertia>
          <ixx>0.16</ixx>
          <ixy>0</ixy>
          <ixz>0</ixz>
          <iyy>0.16</iyy>
          <iyz>0</iyz>
          <izz>0.16</izz>
        </inertia>
      </inertial>
      <visual name="visual">
        <geometry>
          <box>
            <size>0.016 0.083 0.02</size>
          </box>
        </geometry>
        <material>
          <ambient>0.3 0.3 0.3 1</ambient>
          <diffuse>0.7 0.7 0.7 1</diffuse>
          <specular>0.01 0.01 0.01 1</specular>
          <emissive>0 0 0 1</emissive>
        </material>
      </visual>

      <collision name="collision_0">
        <geometry>
          <box>
            <size>0.016 0.083 0.02</size>
          </box>
        </geometry>
        <drake:proximity_properties>
          <drake:rigid_hydroelastic/>
          <!-- <drake:hydroelastic_modulus>1e6</drake:hydroelastic_modulus> -->
          <!-- <drake:hunt_crossley_dissipation>1.0</drake:hunt_crossley_dissipation> -->
          <!-- <drake:mu_static>0.4</drake:mu_static> -->
          <!-- <drake:mu_dynamic>0.4</drake:mu_dynamic> -->
          <drake:relaxation_time>0.1</drake:relaxation_time>
        </drake:proximity_properties>
      </collision>
    </link>

    <link name="right_finger">
      <pose>0.008 0.029 0 0 0 0</pose>
      <inertial>
        <mass>0.05</mass>
        <inertia>
          <ixx>0.16</ixx>
          <ixy>0</ixy>
          <ixz>0</ixz>
          <iyy>0.16</iyy>
          <iyz>0</iyz>
          <izz>0.16</izz>
        </inertia>
      </inertial>
      <visual name="visual">
        <geometry>
          <box>
            <size>0.016 0.083 0.02</size>
          </box>
        </geometry>
        <material>
          <ambient>0.3 0.3 0.3 1</ambient>
          <diffuse>0.7 0.7 0.7 1</diffuse>
          <specular>0.01 0.01 0.01 1</specular>
          <emissive>0 0 0 1</emissive>
        </material>
      </visual>

      <collision name="collision_0">
        <geometry>
          <box>
            <size>0.016 0.083 0.02</size>
          </box>
        </geometry>
        <drake:proximity_properties>
          <drake:rigid_hydroelastic/>
          <!-- <drake:hydroelastic_modulus>1e6</drake:hydroelastic_modulus> -->
          <!-- <drake:hunt_crossley_dissipation>1.0</drake:hunt_crossley_dissipation> -->
          <!-- <drake:mu_static>0.4</drake:mu_static> -->
          <!-- <drake:mu_dynamic>0.4</drake:mu_dynamic> -->
          <drake:relaxation_time>0.1</drake:relaxation_time>
        </drake:proximity_properties>
      </collision>
    </link>

    <joint name="left_finger_sliding_joint" type="prismatic">
      <parent>gripper_base</parent>
      <child>left_finger</child>
      <axis>
        <xyz>1 0 0</xyz>
        <!-- Drake attaches an actuator to all and only joints with a nonzero
             effort limit. -->
        <limit>
          <lower>-0.055</lower>
          <upper>0</upper>
          <effort>80</effort>
          <stiffness>0</stiffness>
          <!-- <dissipation>50</dissipation> -->
        </limit>
        <!-- <dynamics>
          <spring_reference>0</spring_reference>
          <spring_stiffness>0</spring_stiffness>
          <damping>0</damping>
          <friction>0</friction>
        </dynamics> -->
      </axis>
    </joint>

    <joint name="right_finger_sliding_joint" type="prismatic">
      <parent>gripper_base</parent>
      <child>right_finger</child>
      <axis>
        <xyz>1 0 0</xyz>
        <!-- Drake attaches an actuator to all and only joints with a nonzero
             effort limit. -->
        <limit>
          <lower>0</lower>
          <upper>0.055</upper>
          <effort>80</effort>
          <!-- <stiffness>15000</stiffness> -->
          <!-- <dissipation>50</dissipation> -->
        </limit>
        <!-- <dynamics>
          <spring_reference>0</spring_reference>
          <spring_stiffness>0</spring_stiffness>
          <damping>0</damping>
          <friction>0</friction>
        </dynamics> -->
      </axis>
    </joint>
  </model>
</sdf>
